{"uuid": "ac55e758-6c3b-4d29-a6ff-96d2928e08ae", "children": ["67142417-9cd3-4333-99fe-be9f779955ba"], "befores": [{"name": "init_driver", "status": "passed", "start": 1638887457272, "stop": 1638887459160}], "afters": [{"name": "init_driver::0", "status": "broken", "statusDetails": {"message": "selenium.common.exceptions.NoSuchWindowException: Message: no such window: target window already closed\nfrom unknown error: web view not found\n  (Session info: chrome=96.0.4664.55)\n\n", "trace": "  File \"/Users/dbalasub/Library/Python/3.9/lib/python/site-packages/allure_commons/_allure.py\", line 200, in __call__\n    return self._fixture_function(*args, **kwargs)\n  File \"/Library/Frameworks/Python.framework/Versions/3.9/lib/python3.9/site-packages/_pytest/fixtures.py\", line 941, in _teardown_yield_fixture\n    next(it)\n  File \"/Users/dbalasub/PycharmProjects/pythonProject/TestCases/conftest.py\", line 13, in init_driver\n    web_driver.close()\n  File \"/Users/dbalasub/Library/Python/3.9/lib/python/site-packages/selenium/webdriver/remote/webdriver.py\", line 688, in close\n    self.execute(Command.CLOSE)\n  File \"/Users/dbalasub/Library/Python/3.9/lib/python/site-packages/selenium/webdriver/remote/webdriver.py\", line 321, in execute\n    self.error_handler.check_response(response)\n  File \"/Users/dbalasub/Library/Python/3.9/lib/python/site-packages/selenium/webdriver/remote/errorhandler.py\", line 242, in check_response\n    raise exception_class(message, screen, stacktrace)\n"}, "start": 1638887461165, "stop": 1638887461181}], "start": 1638887457272, "stop": 1638887461181}