{"uuid": "5f56a153-7f32-44a0-ae0f-66d3100a1a42", "children": ["2c2a61c4-ba94-44d6-9285-a2903ca04d2a"], "befores": [{"name": "init_driver", "status": "passed", "start": 1639033769667, "stop": 1639033777094}], "afters": [{"name": "init_driver::0", "status": "broken", "statusDetails": {"message": "selenium.common.exceptions.NoSuchWindowException: Message: no such window: target window already closed\nfrom unknown error: web view not found\n  (Session info: chrome=96.0.4664.93)\n\n", "trace": "  File \"/Users/dbalasub/Library/Python/3.9/lib/python/site-packages/allure_commons/_allure.py\", line 200, in __call__\n    return self._fixture_function(*args, **kwargs)\n  File \"/Library/Frameworks/Python.framework/Versions/3.9/lib/python3.9/site-packages/_pytest/fixtures.py\", line 941, in _teardown_yield_fixture\n    next(it)\n  File \"/Users/dbalasub/PycharmProjects/pythonProject/TestCases/conftest.py\", line 13, in init_driver\n    web_driver.close()\n  File \"/Users/dbalasub/Library/Python/3.9/lib/python/site-packages/selenium/webdriver/remote/webdriver.py\", line 688, in close\n    self.execute(Command.CLOSE)\n  File \"/Users/dbalasub/Library/Python/3.9/lib/python/site-packages/selenium/webdriver/remote/webdriver.py\", line 321, in execute\n    self.error_handler.check_response(response)\n  File \"/Users/dbalasub/Library/Python/3.9/lib/python/site-packages/selenium/webdriver/remote/errorhandler.py\", line 242, in check_response\n    raise exception_class(message, screen, stacktrace)\n"}, "start": 1639033912249, "stop": 1639033912253}], "start": 1639033769667, "stop": 1639033912253}